[2022-06-06 04:01:19,144] {taskinstance.py:1160} INFO - Dependencies all met for <TaskInstance: hero_info.hero_api_call scheduled__2022-06-05T04:00:00+00:00 map_index=63 [queued]>
[2022-06-06 04:01:19,208] {taskinstance.py:1160} INFO - Dependencies all met for <TaskInstance: hero_info.hero_api_call scheduled__2022-06-05T04:00:00+00:00 map_index=63 [queued]>
[2022-06-06 04:01:19,208] {taskinstance.py:1357} INFO - 
--------------------------------------------------------------------------------
[2022-06-06 04:01:19,208] {taskinstance.py:1358} INFO - Starting attempt 1 of 2
[2022-06-06 04:01:19,208] {taskinstance.py:1359} INFO - 
--------------------------------------------------------------------------------
[2022-06-06 04:01:19,252] {taskinstance.py:1378} INFO - Executing <Mapped(_PythonDecoratedOperator): hero_api_call> on 2022-06-05 04:00:00+00:00
[2022-06-06 04:01:19,277] {standard_task_runner.py:52} INFO - Started process 6767 to run task
[2022-06-06 04:01:19,297] {standard_task_runner.py:79} INFO - Running: ['***', 'tasks', 'run', 'hero_info', 'hero_api_call', 'scheduled__2022-06-05T04:00:00+00:00', '--job-id', '14513', '--raw', '--subdir', 'DAGS_FOLDER/ingest_heroes.py', '--cfg-path', '/tmp/tmpo4urhkv4', '--map-index', '63', '--error-file', '/tmp/tmpyxcfzt8u']
[2022-06-06 04:01:19,299] {standard_task_runner.py:80} INFO - Job 14513: Subtask hero_api_call
[2022-06-06 04:01:19,622] {task_command.py:370} INFO - Running <TaskInstance: hero_info.hero_api_call scheduled__2022-06-05T04:00:00+00:00 map_index=63 [running]> on host 76384e2d8475
[2022-06-06 04:01:20,096] {taskinstance.py:1570} INFO - Exporting the following env vars:
AIRFLOW_CTX_DAG_OWNER=***
AIRFLOW_CTX_DAG_ID=hero_info
AIRFLOW_CTX_TASK_ID=hero_api_call
AIRFLOW_CTX_EXECUTION_DATE=2022-06-05T04:00:00+00:00
AIRFLOW_CTX_TRY_NUMBER=1
AIRFLOW_CTX_DAG_RUN_ID=scheduled__2022-06-05T04:00:00+00:00
[2022-06-06 04:01:27,616] {taskinstance.py:1890} ERROR - Task failed with exception
Traceback (most recent call last):
  File "/home/airflow/.local/lib/python3.9/site-packages/airflow/decorators/base.py", line 179, in execute
    return_value = super().execute(context)
  File "/home/airflow/.local/lib/python3.9/site-packages/airflow/operators/python.py", line 171, in execute
    return_value = self.execute_callable()
  File "/home/airflow/.local/lib/python3.9/site-packages/airflow/operators/python.py", line 189, in execute_callable
    return self.python_callable(*self.op_args, **self.op_kwargs)
  File "/opt/airflow/dags/ingest_heroes.py", line 143, in hero_api_call
    return json.loads(r.text)
  File "/usr/local/lib/python3.9/json/__init__.py", line 346, in loads
    return _default_decoder.decode(s)
  File "/usr/local/lib/python3.9/json/decoder.py", line 337, in decode
    obj, end = self.raw_decode(s, idx=_w(s, 0).end())
  File "/usr/local/lib/python3.9/json/decoder.py", line 355, in raw_decode
    raise JSONDecodeError("Expecting value", s, err.value) from None
json.decoder.JSONDecodeError: Expecting value: line 1 column 1 (char 0)
[2022-06-06 04:01:27,661] {taskinstance.py:1396} INFO - Marking task as UP_FOR_RETRY. dag_id=hero_info, task_id=hero_api_call, map_index=63, execution_date=20220605T040000, start_date=20220606T040119, end_date=20220606T040127
[2022-06-06 04:01:28,016] {standard_task_runner.py:92} ERROR - Failed to execute job 14513 for task hero_api_call (Expecting value: line 1 column 1 (char 0); 6767)
[2022-06-06 04:01:28,103] {local_task_job.py:156} INFO - Task exited with return code 1
[2022-06-06 04:01:28,784] {local_task_job.py:273} INFO - 0 downstream tasks scheduled from follow-on schedule check
